<sdf version="1.10">
  <model name='humanod_from_mjcf'>
    <static>false</static>
    <self_collide>false</self_collide>
    <allow_auto_disable>true</allow_auto_disable>
    <enable_wind>false</enable_wind>
    <pose>0 0 0 0 0 0</pose>
    <link name='torso'>
      <pose>0 0 1.5 0 0 0</pose>
      <inertial>
        <pose>-0.00386404 0 -0.0463685 0 0.083141200000000012 0</pose>
        <mass>5.8538300000000003</mass>
        <inertia>
          <ixx>0.051274199999999999</ixx>
          <ixy>0</ixy>
          <ixz>0</ixz>
          <iyy>0.031966700000000001</iyy>
          <iyz>0</iyz>
          <izz>0.031149300000000001</izz>
        </inertia>
      </inertial>
      <enable_wind>false</enable_wind>
      <collision name='collision_torso'>
        <pose>0 0 0 1.5708 0 0</pose>
        <geometry>
          <capsule>
            <radius>0.070000000000000007</radius>
            <length>0.14000000000000001</length>
          </capsule>
        </geometry>
        <surface>
          <contact>
            <collide_bitmask>255</collide_bitmask>
          </contact>
          <friction>
            <ode>
              <mu>0.69999999999999996</mu>
            </ode>
          </friction>
        </surface>
      </collision>
      <collision name='collision_upper_waist'>
        <pose>-0.01 0 -0.12 1.5708 0 0</pose>
        <geometry>
          <capsule>
            <radius>0.059999999999999998</radius>
            <length>0.12</length>
          </capsule>
        </geometry>
        <surface>
          <contact>
            <collide_bitmask>255</collide_bitmask>
          </contact>
          <friction>
            <ode>
              <mu>0.69999999999999996</mu>
            </ode>
          </friction>
        </surface>
      </collision>
      <light name='top' type='spot'>
        <pose>0 0 2 0 0 0</pose>
        <cast_shadows>false</cast_shadows>
        <intensity>1</intensity>
        <direction>0 0 -1</direction>
        <diffuse>0.699999988 0.699999988 0.699999988 1</diffuse>
        <specular>0.300000012 0.300000012 0.300000012 1</specular>
        <attenuation>
          <range>10</range>
          <linear>0</linear>
          <constant>1</constant>
          <quadratic>0</quadratic>
        </attenuation>
        <spot>
          <inner_angle>0</inner_angle>
          <outer_angle>1.5708</outer_angle>
          <falloff>2</falloff>
        </spot>
      </light>
      <sensor name='back' type='camera'>
        <pose>-3 0 1 7.8504600000000004e-17 7.8504600000000004e-17 -7.8504600000000004e-17</pose>
        <topic>__default__</topic>
        <update_rate>25</update_rate>
        <enable_metrics>false</enable_metrics>
        <camera>
          <pose>0 0 0 0 0 0</pose>
          <horizontal_fov>1.0469999999999999</horizontal_fov>
          <image>
            <width>320</width>
            <height>240</height>
            <format>RGB_INT8</format>
            <anti_aliasing>4</anti_aliasing>
          </image>
          <clip>
            <near>0.10000000000000001</near>
            <far>100</far>
          </clip>
          <save enabled='false'>
            <path>__default__</path>
          </save>
          <visibility_mask>4294967295</visibility_mask>
          <noise>
            <type>none</type>
            <mean>0</mean>
            <stddev>0</stddev>
          </noise>
          <distortion>
            <k1>0</k1>
            <k2>0</k2>
            <k3>0</k3>
            <p1>0</p1>
            <p2>0</p2>
            <center>0.5 0.5</center>
          </distortion>
          <lens>
            <type>stereographic</type>
            <scale_to_hfov>true</scale_to_hfov>
            <cutoff_angle>1.5708</cutoff_angle>
            <env_texture_size>256</env_texture_size>
          </lens>
        </camera>
      </sensor>
      <sensor name='side' type='camera'>
        <pose>0 -3 1 2.2204499999999999e-16 2.4651903288156619e-32 1.5708</pose>
        <topic>__default__</topic>
        <update_rate>25</update_rate>
        <enable_metrics>false</enable_metrics>
        <camera>
          <pose>0 0 0 0 0 0</pose>
          <horizontal_fov>1.0469999999999999</horizontal_fov>
          <image>
            <width>320</width>
            <height>240</height>
            <format>RGB_INT8</format>
            <anti_aliasing>4</anti_aliasing>
          </image>
          <clip>
            <near>0.10000000000000001</near>
            <far>100</far>
          </clip>
          <save enabled='false'>
            <path>__default__</path>
          </save>
          <visibility_mask>4294967295</visibility_mask>
          <noise>
            <type>none</type>
            <mean>0</mean>
            <stddev>0</stddev>
          </noise>
          <distortion>
            <k1>0</k1>
            <k2>0</k2>
            <k3>0</k3>
            <p1>0</p1>
            <p2>0</p2>
            <center>0.5 0.5</center>
          </distortion>
          <lens>
            <type>stereographic</type>
            <scale_to_hfov>true</scale_to_hfov>
            <cutoff_angle>1.5708</cutoff_angle>
            <env_texture_size>256</env_texture_size>
          </lens>
        </camera>
      </sensor>
      <visual name='visual_torso'>
        <pose>0 0 0 1.5708 0 0</pose>
        <geometry>
          <capsule>
            <radius>0.070000000000000007</radius>
            <length>0.14000000000000001</length>
          </capsule>
        </geometry>
        <cast_shadows>true</cast_shadows>
        <laser_retro>0</laser_retro>
        <transparency>0</transparency>
        <visibility_flags>4294967295</visibility_flags>
        <material>
          <ambient>0.800000012 0.600000024 0.400000006 1</ambient>
          <diffuse>0.800000012 0.600000024 0.400000006 1</diffuse>
          <specular>0.5 0.5 0.5 1</specular>
          <emissive>0 0 0 1</emissive>
          <render_order>0</render_order>
          <lighting>true</lighting>
          <double_sided>false</double_sided>
          <shader type='pixel'/>
        </material>
      </visual>
      <visual name='visual_upper_waist'>
        <pose>-0.01 0 -0.12 1.5708 0 0</pose>
        <geometry>
          <capsule>
            <radius>0.059999999999999998</radius>
            <length>0.12</length>
          </capsule>
        </geometry>
        <cast_shadows>true</cast_shadows>
        <laser_retro>0</laser_retro>
        <transparency>0</transparency>
        <visibility_flags>4294967295</visibility_flags>
        <material>
          <ambient>0.800000012 0.600000024 0.400000006 1</ambient>
          <diffuse>0.800000012 0.600000024 0.400000006 1</diffuse>
          <specular>0.5 0.5 0.5 1</specular>
          <emissive>0 0 0 1</emissive>
          <render_order>0</render_order>
          <lighting>true</lighting>
          <double_sided>false</double_sided>
          <shader type='pixel'/>
        </material>
      </visual>
    </link>
    <link name='head'>
      <pose relative_to='torso'>0 0 0.19 0 0 0</pose>
      <inertial>
        <pose>0 0 0 0 0 0</pose>
        <mass>3.0536300000000001</mass>
        <inertia>
          <ixx>0.0098937499999999998</ixx>
          <ixy>0</ixy>
          <ixz>0</ixz>
          <iyy>0.0098937499999999998</iyy>
          <iyz>0</iyz>
          <izz>0.0098937499999999998</izz>
        </inertia>
      </inertial>
      <enable_wind>false</enable_wind>
      <collision name='collision_head'>
        <pose>0 0 0 0 0 0</pose>
        <geometry>
          <sphere>
            <radius>0.089999999999999997</radius>
          </sphere>
        </geometry>
        <surface>
          <contact>
            <collide_bitmask>255</collide_bitmask>
          </contact>
          <friction>
            <ode>
              <mu>0.69999999999999996</mu>
            </ode>
          </friction>
        </surface>
      </collision>
      <sensor name='egocentric' type='camera'>
        <pose>0.089999999999999997 0 0 2.0641799999999998e-16 0.095166200000000006 -3.2285999999999994e-16</pose>
        <topic>__default__</topic>
        <update_rate>25</update_rate>
        <enable_metrics>false</enable_metrics>
        <camera>
          <pose>0 0 0 0 0 0</pose>
          <horizontal_fov>1.0469999999999999</horizontal_fov>
          <image>
            <width>320</width>
            <height>240</height>
            <format>RGB_INT8</format>
            <anti_aliasing>4</anti_aliasing>
          </image>
          <clip>
            <near>0.10000000000000001</near>
            <far>100</far>
          </clip>
          <save enabled='false'>
            <path>__default__</path>
          </save>
          <visibility_mask>4294967295</visibility_mask>
          <noise>
            <type>none</type>
            <mean>0</mean>
            <stddev>0</stddev>
          </noise>
          <distortion>
            <k1>0</k1>
            <k2>0</k2>
            <k3>0</k3>
            <p1>0</p1>
            <p2>0</p2>
            <center>0.5 0.5</center>
          </distortion>
          <lens>
            <type>stereographic</type>
            <scale_to_hfov>true</scale_to_hfov>
            <cutoff_angle>1.5708</cutoff_angle>
            <env_texture_size>256</env_texture_size>
          </lens>
        </camera>
      </sensor>
      <visual name='visual_head'>
        <pose>0 0 0 0 0 0</pose>
        <geometry>
          <sphere>
            <radius>0.089999999999999997</radius>
          </sphere>
        </geometry>
        <cast_shadows>true</cast_shadows>
        <laser_retro>0</laser_retro>
        <transparency>0</transparency>
        <visibility_flags>4294967295</visibility_flags>
        <material>
          <ambient>0.800000012 0.600000024 0.400000006 1</ambient>
          <diffuse>0.800000012 0.600000024 0.400000006 1</diffuse>
          <specular>0.5 0.5 0.5 1</specular>
          <emissive>0 0 0 1</emissive>
          <render_order>0</render_order>
          <lighting>true</lighting>
          <double_sided>false</double_sided>
          <shader type='pixel'/>
        </material>
      </visual>
    </link>
    <link name='lower_waist'>
      <pose relative_to='torso'>-0.01 0 -0.26000000000000001 0 0 0</pose>
      <inertial>
        <pose>0 0 0 1.5708 0 0</pose>
        <mass>2.2619500000000001</mass>
        <inertia>
          <ixx>0.0098530400000000004</ixx>
          <ixy>0</ixy>
          <ixz>0</ixz>
          <iyy>0.0098530400000000004</iyy>
          <iyz>0</iyz>
          <izz>0.0037457800000000002</izz>
        </inertia>
      </inertial>
      <enable_wind>false</enable_wind>
      <collision name='collision_lower_waist'>
        <pose>0 0 0 1.5708 0 0</pose>
        <geometry>
          <capsule>
            <radius>0.059999999999999998</radius>
            <length>0.12</length>
          </capsule>
        </geometry>
        <surface>
          <contact>
            <collide_bitmask>255</collide_bitmask>
          </contact>
          <friction>
            <ode>
              <mu>0.69999999999999996</mu>
            </ode>
          </friction>
        </surface>
      </collision>
      <visual name='visual_lower_waist'>
        <pose>0 0 0 1.5708 0 0</pose>
        <geometry>
          <capsule>
            <radius>0.059999999999999998</radius>
            <length>0.12</length>
          </capsule>
        </geometry>
        <cast_shadows>true</cast_shadows>
        <laser_retro>0</laser_retro>
        <transparency>0</transparency>
        <visibility_flags>4294967295</visibility_flags>
        <material>
          <ambient>0.800000012 0.600000024 0.400000006 1</ambient>
          <diffuse>0.800000012 0.600000024 0.400000006 1</diffuse>
          <specular>0.5 0.5 0.5 1</specular>
          <emissive>0 0 0 1</emissive>
          <render_order>0</render_order>
          <lighting>true</lighting>
          <double_sided>false</double_sided>
          <shader type='pixel'/>
        </material>
      </visual>
    </link>
    <link name='lower_waist_dummy_0'>
      <pose relative_to='lower_waist'>0 0 0 0 0 0</pose>
      <inertial>
        <pose>0 0 0 0 0 0</pose>
        <mass>9.9999999999999995e-07</mass>
        <inertia>
          <ixx>3.9999999999999998e-07</ixx>
          <ixy>0</ixy>
          <ixz>0</ixz>
          <iyy>3.9999999999999998e-07</iyy>
          <iyz>0</iyz>
          <izz>3.9999999999999998e-07</izz>
        </inertia>
      </inertial>
      <enable_wind>false</enable_wind>
    </link>
    <link name='pelvis'>
      <pose relative_to='lower_waist'>0 0 -0.16500000000000001 0 0 0</pose>
      <inertial>
        <pose>-0.02 0 0 1.5708 0 0</pose>
        <mass>6.6161899999999996</mass>
        <inertia>
          <ixx>0.052318000000000003</ixx>
          <ixy>0</ixy>
          <ixz>0</ixz>
          <iyy>0.052318000000000003</iyy>
          <iyz>0</iyz>
          <izz>0.024322099999999999</izz>
        </inertia>
      </inertial>
      <enable_wind>false</enable_wind>
      <collision name='collision_butt'>
        <pose>-0.02 0 0 1.5708 0 0</pose>
        <geometry>
          <capsule>
            <radius>0.089999999999999997</radius>
            <length>0.14000000000000001</length>
          </capsule>
        </geometry>
        <surface>
          <contact>
            <collide_bitmask>255</collide_bitmask>
          </contact>
          <friction>
            <ode>
              <mu>0.69999999999999996</mu>
            </ode>
          </friction>
        </surface>
      </collision>
      <visual name='visual_butt'>
        <pose>-0.02 0 0 1.5708 0 0</pose>
        <geometry>
          <capsule>
            <radius>0.089999999999999997</radius>
            <length>0.14000000000000001</length>
          </capsule>
        </geometry>
        <cast_shadows>true</cast_shadows>
        <laser_retro>0</laser_retro>
        <transparency>0</transparency>
        <visibility_flags>4294967295</visibility_flags>
        <material>
          <ambient>0.800000012 0.600000024 0.400000006 1</ambient>
          <diffuse>0.800000012 0.600000024 0.400000006 1</diffuse>
          <specular>0.5 0.5 0.5 1</specular>
          <emissive>0 0 0 1</emissive>
          <render_order>0</render_order>
          <lighting>true</lighting>
          <double_sided>false</double_sided>
          <shader type='pixel'/>
        </material>
      </visual>
    </link>
    <link name='right_thigh'>
      <pose relative_to='pelvis'>0 -0.10000000000000001 -0.040000000000000001 0 0 0</pose>
      <inertial>
        <pose>0 0.0050000000000000001 -0.17000000000000001 0.029403299999999997 0 0</pose>
        <mass>4.7517500000000004</mass>
        <inertia>
          <ixx>0.074951699999999996</ixx>
          <ixy>0</ixy>
          <ixz>0</ixz>
          <iyy>0.074951699999999996</iyy>
          <iyz>0</iyz>
          <izz>0.0082274300000000009</izz>
        </inertia>
      </inertial>
      <enable_wind>false</enable_wind>
      <collision name='collision_right_thigh'>
        <pose>0 0.0050000000000000001 -0.17000000000000001 0.029403299999999997 0 0</pose>
        <geometry>
          <capsule>
            <radius>0.059999999999999998</radius>
            <length>0.34014699999999998</length>
          </capsule>
        </geometry>
        <surface>
          <contact>
            <collide_bitmask>255</collide_bitmask>
          </contact>
          <friction>
            <ode>
              <mu>0.69999999999999996</mu>
            </ode>
          </friction>
        </surface>
      </collision>
      <visual name='visual_right_thigh'>
        <pose>0 0.0050000000000000001 -0.17000000000000001 0.029403299999999997 0 0</pose>
        <geometry>
          <capsule>
            <radius>0.059999999999999998</radius>
            <length>0.34014699999999998</length>
          </capsule>
        </geometry>
        <cast_shadows>true</cast_shadows>
        <laser_retro>0</laser_retro>
        <transparency>0</transparency>
        <visibility_flags>4294967295</visibility_flags>
        <material>
          <ambient>0.800000012 0.600000024 0.400000006 1</ambient>
          <diffuse>0.800000012 0.600000024 0.400000006 1</diffuse>
          <specular>0.5 0.5 0.5 1</specular>
          <emissive>0 0 0 1</emissive>
          <render_order>0</render_order>
          <lighting>true</lighting>
          <double_sided>false</double_sided>
          <shader type='pixel'/>
        </material>
      </visual>
    </link>
    <link name='right_thigh_dummy_0'>
      <pose relative_to='right_thigh'>0 0 0 0 0 0</pose>
      <inertial>
        <pose>0 0 0 0 0 0</pose>
        <mass>9.9999999999999995e-07</mass>
        <inertia>
          <ixx>3.9999999999999998e-07</ixx>
          <ixy>0</ixy>
          <ixz>0</ixz>
          <iyy>3.9999999999999998e-07</iyy>
          <iyz>0</iyz>
          <izz>3.9999999999999998e-07</izz>
        </inertia>
      </inertial>
      <enable_wind>false</enable_wind>
    </link>
    <link name='right_thigh_dummy_1'>
      <pose relative_to='right_thigh'>0 0 0 0 0 0</pose>
      <inertial>
        <pose>0 0 0 0 0 0</pose>
        <mass>9.9999999999999995e-07</mass>
        <inertia>
          <ixx>3.9999999999999998e-07</ixx>
          <ixy>0</ixy>
          <ixz>0</ixz>
          <iyy>3.9999999999999998e-07</iyy>
          <iyz>0</iyz>
          <izz>3.9999999999999998e-07</izz>
        </inertia>
      </inertial>
      <enable_wind>false</enable_wind>
    </link>
    <link name='right_shin'>
      <pose relative_to='right_thigh'>0 0.01 -0.40300000000000002 0 0 0</pose>
      <inertial>
        <pose>0 0 -0.14999999999999999 0 0 0</pose>
        <mass>2.7557</mass>
        <inertia>
          <ixx>0.032607999999999998</ixx>
          <ixy>0</ixy>
          <ixz>0</ixz>
          <iyy>0.032607999999999998</iyy>
          <iyz>0</iyz>
          <izz>0.0031898899999999999</izz>
        </inertia>
      </inertial>
      <enable_wind>false</enable_wind>
      <collision name='collision_right_shin'>
        <pose>0 0 -0.14999999999999999 0 0 0</pose>
        <geometry>
          <capsule>
            <radius>0.049000000000000002</radius>
            <length>0.29999999999999999</length>
          </capsule>
        </geometry>
        <surface>
          <contact>
            <collide_bitmask>255</collide_bitmask>
          </contact>
          <friction>
            <ode>
              <mu>0.69999999999999996</mu>
            </ode>
          </friction>
        </surface>
      </collision>
      <visual name='visual_right_shin'>
        <pose>0 0 -0.14999999999999999 0 0 0</pose>
        <geometry>
          <capsule>
            <radius>0.049000000000000002</radius>
            <length>0.29999999999999999</length>
          </capsule>
        </geometry>
        <cast_shadows>true</cast_shadows>
        <laser_retro>0</laser_retro>
        <transparency>0</transparency>
        <visibility_flags>4294967295</visibility_flags>
        <material>
          <ambient>0.800000012 0.600000024 0.400000006 1</ambient>
          <diffuse>0.800000012 0.600000024 0.400000006 1</diffuse>
          <specular>0.5 0.5 0.5 1</specular>
          <emissive>0 0 0 1</emissive>
          <render_order>0</render_order>
          <lighting>true</lighting>
          <double_sided>false</double_sided>
          <shader type='pixel'/>
        </material>
      </visual>
    </link>
    <link name='right_foot'>
      <pose relative_to='right_shin'>0 0 -0.39000000000000001 0 0 0</pose>
      <inertial>
        <pose>0.035000000000000003 -0.01 0 2.6535897933410511e-06 -1.5707926536359933 3.1415926535897931</pose>
        <mass>1.13114</mass>
        <inertia>
          <ixx>0.0064464600000000002</ixx>
          <ixy>0</ixy>
          <ixz>0</ixz>
          <iyy>0.0059437200000000004</iyy>
          <iyz>0</iyz>
          <izz>0.00090301699999999999</izz>
        </inertia>
      </inertial>
      <enable_wind>false</enable_wind>
      <collision name='collision_right_right_foot'>
        <pose>0.035000000000000003 -0.029999999999999999 0 -1.5708000000000009 -1.47584 1.4758400000000012</pose>
        <geometry>
          <capsule>
            <radius>0.027</radius>
            <length>0.21095</length>
          </capsule>
        </geometry>
        <surface>
          <contact>
            <collide_bitmask>255</collide_bitmask>
          </contact>
          <friction>
            <ode>
              <mu>0.69999999999999996</mu>
            </ode>
          </friction>
        </surface>
      </collision>
      <collision name='collision_left_right_foot'>
        <pose>0.035000000000000003 0.01 0 1.5708000000000009 -1.47584 -1.4758400000000012</pose>
        <geometry>
          <capsule>
            <radius>0.027</radius>
            <length>0.21095</length>
          </capsule>
        </geometry>
        <surface>
          <contact>
            <collide_bitmask>255</collide_bitmask>
          </contact>
          <friction>
            <ode>
              <mu>0.69999999999999996</mu>
            </ode>
          </friction>
        </surface>
      </collision>
      <visual name='visual_right_right_foot'>
        <pose>0.035000000000000003 -0.029999999999999999 0 -1.5708000000000009 -1.47584 1.4758400000000012</pose>
        <geometry>
          <capsule>
            <radius>0.027</radius>
            <length>0.21095</length>
          </capsule>
        </geometry>
        <cast_shadows>true</cast_shadows>
        <laser_retro>0</laser_retro>
        <transparency>0</transparency>
        <visibility_flags>4294967295</visibility_flags>
        <material>
          <ambient>0.800000012 0.600000024 0.400000006 1</ambient>
          <diffuse>0.800000012 0.600000024 0.400000006 1</diffuse>
          <specular>0.5 0.5 0.5 1</specular>
          <emissive>0 0 0 1</emissive>
          <render_order>0</render_order>
          <lighting>true</lighting>
          <double_sided>false</double_sided>
          <shader type='pixel'/>
        </material>
      </visual>
      <visual name='visual_left_right_foot'>
        <pose>0.035000000000000003 0.01 0 1.5708000000000009 -1.47584 -1.4758400000000012</pose>
        <geometry>
          <capsule>
            <radius>0.027</radius>
            <length>0.21095</length>
          </capsule>
        </geometry>
        <cast_shadows>true</cast_shadows>
        <laser_retro>0</laser_retro>
        <transparency>0</transparency>
        <visibility_flags>4294967295</visibility_flags>
        <material>
          <ambient>0.800000012 0.600000024 0.400000006 1</ambient>
          <diffuse>0.800000012 0.600000024 0.400000006 1</diffuse>
          <specular>0.5 0.5 0.5 1</specular>
          <emissive>0 0 0 1</emissive>
          <render_order>0</render_order>
          <lighting>true</lighting>
          <double_sided>false</double_sided>
          <shader type='pixel'/>
        </material>
      </visual>
    </link>
    <link name='right_foot_dummy_0'>
      <pose relative_to='right_foot'>0 0 0 0 0 0</pose>
      <inertial>
        <pose>0 0 0 0 0 0</pose>
        <mass>9.9999999999999995e-07</mass>
        <inertia>
          <ixx>3.9999999999999998e-07</ixx>
          <ixy>0</ixy>
          <ixz>0</ixz>
          <iyy>3.9999999999999998e-07</iyy>
          <iyz>0</iyz>
          <izz>3.9999999999999998e-07</izz>
        </inertia>
      </inertial>
      <enable_wind>false</enable_wind>
    </link>
    <link name='left_thigh'>
      <pose relative_to='pelvis'>0 0.10000000000000001 -0.040000000000000001 0 0 0</pose>
      <inertial>
        <pose>0 -0.0050000000000000001 -0.17000000000000001 -0.029403299999999997 0 0</pose>
        <mass>4.7517500000000004</mass>
        <inertia>
          <ixx>0.074951699999999996</ixx>
          <ixy>0</ixy>
          <ixz>0</ixz>
          <iyy>0.074951699999999996</iyy>
          <iyz>0</iyz>
          <izz>0.0082274300000000009</izz>
        </inertia>
      </inertial>
      <enable_wind>false</enable_wind>
      <collision name='collision_left_thigh'>
        <pose>0 -0.0050000000000000001 -0.17000000000000001 -0.029403299999999997 0 0</pose>
        <geometry>
          <capsule>
            <radius>0.059999999999999998</radius>
            <length>0.34014699999999998</length>
          </capsule>
        </geometry>
        <surface>
          <contact>
            <collide_bitmask>255</collide_bitmask>
          </contact>
          <friction>
            <ode>
              <mu>0.69999999999999996</mu>
            </ode>
          </friction>
        </surface>
      </collision>
      <visual name='visual_left_thigh'>
        <pose>0 -0.0050000000000000001 -0.17000000000000001 -0.029403299999999997 0 0</pose>
        <geometry>
          <capsule>
            <radius>0.059999999999999998</radius>
            <length>0.34014699999999998</length>
          </capsule>
        </geometry>
        <cast_shadows>true</cast_shadows>
        <laser_retro>0</laser_retro>
        <transparency>0</transparency>
        <visibility_flags>4294967295</visibility_flags>
        <material>
          <ambient>0.800000012 0.600000024 0.400000006 1</ambient>
          <diffuse>0.800000012 0.600000024 0.400000006 1</diffuse>
          <specular>0.5 0.5 0.5 1</specular>
          <emissive>0 0 0 1</emissive>
          <render_order>0</render_order>
          <lighting>true</lighting>
          <double_sided>false</double_sided>
          <shader type='pixel'/>
        </material>
      </visual>
    </link>
    <link name='left_thigh_dummy_0'>
      <pose relative_to='left_thigh'>0 0 0 0 0 0</pose>
      <inertial>
        <pose>0 0 0 0 0 0</pose>
        <mass>9.9999999999999995e-07</mass>
        <inertia>
          <ixx>3.9999999999999998e-07</ixx>
          <ixy>0</ixy>
          <ixz>0</ixz>
          <iyy>3.9999999999999998e-07</iyy>
          <iyz>0</iyz>
          <izz>3.9999999999999998e-07</izz>
        </inertia>
      </inertial>
      <enable_wind>false</enable_wind>
    </link>
    <link name='left_thigh_dummy_1'>
      <pose relative_to='left_thigh'>0 0 0 0 0 0</pose>
      <inertial>
        <pose>0 0 0 0 0 0</pose>
        <mass>9.9999999999999995e-07</mass>
        <inertia>
          <ixx>3.9999999999999998e-07</ixx>
          <ixy>0</ixy>
          <ixz>0</ixz>
          <iyy>3.9999999999999998e-07</iyy>
          <iyz>0</iyz>
          <izz>3.9999999999999998e-07</izz>
        </inertia>
      </inertial>
      <enable_wind>false</enable_wind>
    </link>
    <link name='left_shin'>
      <pose relative_to='left_thigh'>0 -0.01 -0.40300000000000002 0 0 0</pose>
      <inertial>
        <pose>0 0 -0.14999999999999999 0 0 0</pose>
        <mass>2.7557</mass>
        <inertia>
          <ixx>0.032607999999999998</ixx>
          <ixy>0</ixy>
          <ixz>0</ixz>
          <iyy>0.032607999999999998</iyy>
          <iyz>0</iyz>
          <izz>0.0031898899999999999</izz>
        </inertia>
      </inertial>
      <enable_wind>false</enable_wind>
      <collision name='collision_left_shin'>
        <pose>0 0 -0.14999999999999999 0 0 0</pose>
        <geometry>
          <capsule>
            <radius>0.049000000000000002</radius>
            <length>0.29999999999999999</length>
          </capsule>
        </geometry>
        <surface>
          <contact>
            <collide_bitmask>255</collide_bitmask>
          </contact>
          <friction>
            <ode>
              <mu>0.69999999999999996</mu>
            </ode>
          </friction>
        </surface>
      </collision>
      <visual name='visual_left_shin'>
        <pose>0 0 -0.14999999999999999 0 0 0</pose>
        <geometry>
          <capsule>
            <radius>0.049000000000000002</radius>
            <length>0.29999999999999999</length>
          </capsule>
        </geometry>
        <cast_shadows>true</cast_shadows>
        <laser_retro>0</laser_retro>
        <transparency>0</transparency>
        <visibility_flags>4294967295</visibility_flags>
        <material>
          <ambient>0.800000012 0.600000024 0.400000006 1</ambient>
          <diffuse>0.800000012 0.600000024 0.400000006 1</diffuse>
          <specular>0.5 0.5 0.5 1</specular>
          <emissive>0 0 0 1</emissive>
          <render_order>0</render_order>
          <lighting>true</lighting>
          <double_sided>false</double_sided>
          <shader type='pixel'/>
        </material>
      </visual>
    </link>
    <link name='left_foot'>
      <pose relative_to='left_shin'>0 0 -0.39000000000000001 0 0 0</pose>
      <inertial>
        <pose>0.035000000000000003 0.01 0 2.6535897933410511e-06 -1.5707926536359933 3.1415926535897931</pose>
        <mass>1.13114</mass>
        <inertia>
          <ixx>0.0064464600000000002</ixx>
          <ixy>0</ixy>
          <ixz>0</ixz>
          <iyy>0.0059437200000000004</iyy>
          <iyz>0</iyz>
          <izz>0.00090301699999999999</izz>
        </inertia>
      </inertial>
      <enable_wind>false</enable_wind>
      <collision name='collision_left_left_foot'>
        <pose>0.035000000000000003 0.029999999999999999 0 1.5708000000000009 -1.47584 -1.4758400000000012</pose>
        <geometry>
          <capsule>
            <radius>0.027</radius>
            <length>0.21095</length>
          </capsule>
        </geometry>
        <surface>
          <contact>
            <collide_bitmask>255</collide_bitmask>
          </contact>
          <friction>
            <ode>
              <mu>0.69999999999999996</mu>
            </ode>
          </friction>
        </surface>
      </collision>
      <collision name='collision_right_left_foot'>
        <pose>0.035000000000000003 -0.01 0 -1.5708000000000009 -1.47584 1.4758400000000012</pose>
        <geometry>
          <capsule>
            <radius>0.027</radius>
            <length>0.21095</length>
          </capsule>
        </geometry>
        <surface>
          <contact>
            <collide_bitmask>255</collide_bitmask>
          </contact>
          <friction>
            <ode>
              <mu>0.69999999999999996</mu>
            </ode>
          </friction>
        </surface>
      </collision>
      <visual name='visual_left_left_foot'>
        <pose>0.035000000000000003 0.029999999999999999 0 1.5708000000000009 -1.47584 -1.4758400000000012</pose>
        <geometry>
          <capsule>
            <radius>0.027</radius>
            <length>0.21095</length>
          </capsule>
        </geometry>
        <cast_shadows>true</cast_shadows>
        <laser_retro>0</laser_retro>
        <transparency>0</transparency>
        <visibility_flags>4294967295</visibility_flags>
        <material>
          <ambient>0.800000012 0.600000024 0.400000006 1</ambient>
          <diffuse>0.800000012 0.600000024 0.400000006 1</diffuse>
          <specular>0.5 0.5 0.5 1</specular>
          <emissive>0 0 0 1</emissive>
          <render_order>0</render_order>
          <lighting>true</lighting>
          <double_sided>false</double_sided>
          <shader type='pixel'/>
        </material>
      </visual>
      <visual name='visual_right_left_foot'>
        <pose>0.035000000000000003 -0.01 0 -1.5708000000000009 -1.47584 1.4758400000000012</pose>
        <geometry>
          <capsule>
            <radius>0.027</radius>
            <length>0.21095</length>
          </capsule>
        </geometry>
        <cast_shadows>true</cast_shadows>
        <laser_retro>0</laser_retro>
        <transparency>0</transparency>
        <visibility_flags>4294967295</visibility_flags>
        <material>
          <ambient>0.800000012 0.600000024 0.400000006 1</ambient>
          <diffuse>0.800000012 0.600000024 0.400000006 1</diffuse>
          <specular>0.5 0.5 0.5 1</specular>
          <emissive>0 0 0 1</emissive>
          <render_order>0</render_order>
          <lighting>true</lighting>
          <double_sided>false</double_sided>
          <shader type='pixel'/>
        </material>
      </visual>
    </link>
    <link name='left_foot_dummy_0'>
      <pose relative_to='left_foot'>0 0 0 0 0 0</pose>
      <inertial>
        <pose>0 0 0 0 0 0</pose>
        <mass>9.9999999999999995e-07</mass>
        <inertia>
          <ixx>3.9999999999999998e-07</ixx>
          <ixy>0</ixy>
          <ixz>0</ixz>
          <iyy>3.9999999999999998e-07</iyy>
          <iyz>0</iyz>
          <izz>3.9999999999999998e-07</izz>
        </inertia>
      </inertial>
      <enable_wind>false</enable_wind>
    </link>
    <link name='right_upper_arm'>
      <pose relative_to='torso'>0 -0.17000000000000001 0.059999999999999998 0 0 0</pose>
      <inertial>
        <pose>0.080000000000000002 -0.080000000000000002 -0.080000000000000002 -0.78539800000000026 -0.61548000000000003 0.26179900000000006</pose>
        <mass>1.6610799999999999</mass>
        <inertia>
          <ixx>0.015905499999999999</ixx>
          <ixy>0</ixy>
          <ixz>0</ixz>
          <iyy>0.015905499999999999</iyy>
          <iyz>0</iyz>
          <izz>0.00128597</izz>
        </inertia>
      </inertial>
      <enable_wind>false</enable_wind>
      <collision name='collision_right_upper_arm'>
        <pose>0.080000000000000002 -0.080000000000000002 -0.080000000000000002 -0.78539800000000026 -0.61548000000000003 0.26179900000000006</pose>
        <geometry>
          <capsule>
            <radius>0.040000000000000001</radius>
            <length>0.27712799999999999</length>
          </capsule>
        </geometry>
        <surface>
          <contact>
            <collide_bitmask>255</collide_bitmask>
          </contact>
          <friction>
            <ode>
              <mu>0.69999999999999996</mu>
            </ode>
          </friction>
        </surface>
      </collision>
      <visual name='visual_right_upper_arm'>
        <pose>0.080000000000000002 -0.080000000000000002 -0.080000000000000002 -0.78539800000000026 -0.61548000000000003 0.26179900000000006</pose>
        <geometry>
          <capsule>
            <radius>0.040000000000000001</radius>
            <length>0.27712799999999999</length>
          </capsule>
        </geometry>
        <cast_shadows>true</cast_shadows>
        <laser_retro>0</laser_retro>
        <transparency>0</transparency>
        <visibility_flags>4294967295</visibility_flags>
        <material>
          <ambient>0.800000012 0.600000024 0.400000006 1</ambient>
          <diffuse>0.800000012 0.600000024 0.400000006 1</diffuse>
          <specular>0.5 0.5 0.5 1</specular>
          <emissive>0 0 0 1</emissive>
          <render_order>0</render_order>
          <lighting>true</lighting>
          <double_sided>false</double_sided>
          <shader type='pixel'/>
        </material>
      </visual>
    </link>
    <link name='right_upper_arm_dummy_0'>
      <pose relative_to='right_upper_arm'>0 0 0 0 0 0</pose>
      <inertial>
        <pose>0 0 0 0 0 0</pose>
        <mass>9.9999999999999995e-07</mass>
        <inertia>
          <ixx>3.9999999999999998e-07</ixx>
          <ixy>0</ixy>
          <ixz>0</ixz>
          <iyy>3.9999999999999998e-07</iyy>
          <iyz>0</iyz>
          <izz>3.9999999999999998e-07</izz>
        </inertia>
      </inertial>
      <enable_wind>false</enable_wind>
    </link>
    <link name='right_lower_arm'>
      <pose relative_to='right_upper_arm'>0.17999999999999999 -0.17999999999999999 -0.17999999999999999 0 0 0</pose>
      <inertial>
        <pose>0.089999999999999997 0.089999999999999997 0.089999999999999997 2.3561899999999998 -0.61548000000000003 -1.3089999999999999</pose>
        <mass>0.96145800000000003</mass>
        <inertia>
          <ixx>0.0084016200000000003</ixx>
          <ixy>0</ixy>
          <ixz>0</ixz>
          <iyy>0.0084016200000000003</iyy>
          <iyz>0</iyz>
          <izz>0.00044998800000000002</izz>
        </inertia>
      </inertial>
      <enable_wind>false</enable_wind>
      <collision name='collision_right_lower_arm'>
        <pose>0.089999999999999997 0.089999999999999997 0.089999999999999997 2.3561899999999998 -0.61548000000000003 -1.3089999999999999</pose>
        <geometry>
          <capsule>
            <radius>0.031</radius>
            <length>0.27712799999999999</length>
          </capsule>
        </geometry>
        <surface>
          <contact>
            <collide_bitmask>255</collide_bitmask>
          </contact>
          <friction>
            <ode>
              <mu>0.69999999999999996</mu>
            </ode>
          </friction>
        </surface>
      </collision>
      <visual name='visual_right_lower_arm'>
        <pose>0.089999999999999997 0.089999999999999997 0.089999999999999997 2.3561899999999998 -0.61548000000000003 -1.3089999999999999</pose>
        <geometry>
          <capsule>
            <radius>0.031</radius>
            <length>0.27712799999999999</length>
          </capsule>
        </geometry>
        <cast_shadows>true</cast_shadows>
        <laser_retro>0</laser_retro>
        <transparency>0</transparency>
        <visibility_flags>4294967295</visibility_flags>
        <material>
          <ambient>0.800000012 0.600000024 0.400000006 1</ambient>
          <diffuse>0.800000012 0.600000024 0.400000006 1</diffuse>
          <specular>0.5 0.5 0.5 1</specular>
          <emissive>0 0 0 1</emissive>
          <render_order>0</render_order>
          <lighting>true</lighting>
          <double_sided>false</double_sided>
          <shader type='pixel'/>
        </material>
      </visual>
    </link>
    <link name='right_hand'>
      <pose relative_to='right_lower_arm'>0.17999999999999999 0.17999999999999999 0.17999999999999999 0 0 0</pose>
      <inertial>
        <pose>0 0 0 -0.78539800000000026 0.61548000000000003 -0.26179900000000006</pose>
        <mass>0.26808300000000002</mass>
        <inertia>
          <ixx>0.00017157300000000001</ixx>
          <ixy>0</ixy>
          <ixz>0</ixz>
          <iyy>0.00017157300000000001</iyy>
          <iyz>0</iyz>
          <izz>0.00017157300000000001</izz>
        </inertia>
      </inertial>
      <enable_wind>false</enable_wind>
      <collision name='collision_right_hand'>
        <pose>0 0 0 -0.78539800000000026 0.61548000000000003 -0.26179900000000006</pose>
        <geometry>
          <sphere>
            <radius>0.040000000000000001</radius>
          </sphere>
        </geometry>
        <surface>
          <contact>
            <collide_bitmask>255</collide_bitmask>
          </contact>
          <friction>
            <ode>
              <mu>0.69999999999999996</mu>
            </ode>
          </friction>
        </surface>
      </collision>
      <visual name='visual_right_hand'>
        <pose>0 0 0 -0.78539800000000026 0.61548000000000003 -0.26179900000000006</pose>
        <geometry>
          <sphere>
            <radius>0.040000000000000001</radius>
          </sphere>
        </geometry>
        <cast_shadows>true</cast_shadows>
        <laser_retro>0</laser_retro>
        <transparency>0</transparency>
        <visibility_flags>4294967295</visibility_flags>
        <material>
          <ambient>0.800000012 0.600000024 0.400000006 1</ambient>
          <diffuse>0.800000012 0.600000024 0.400000006 1</diffuse>
          <specular>0.5 0.5 0.5 1</specular>
          <emissive>0 0 0 1</emissive>
          <render_order>0</render_order>
          <lighting>true</lighting>
          <double_sided>false</double_sided>
          <shader type='pixel'/>
        </material>
      </visual>
    </link>
    <link name='left_upper_arm'>
      <pose relative_to='torso'>0 0.17000000000000001 0.059999999999999998 0 0 0</pose>
      <inertial>
        <pose>0.080000000000000002 0.080000000000000002 -0.080000000000000002 0.78539800000000026 -0.61548000000000003 -0.26179900000000006</pose>
        <mass>1.6610799999999999</mass>
        <inertia>
          <ixx>0.015905499999999999</ixx>
          <ixy>0</ixy>
          <ixz>0</ixz>
          <iyy>0.015905499999999999</iyy>
          <iyz>0</iyz>
          <izz>0.00128597</izz>
        </inertia>
      </inertial>
      <enable_wind>false</enable_wind>
      <collision name='collision_left_upper_arm'>
        <pose>0.080000000000000002 0.080000000000000002 -0.080000000000000002 0.78539800000000026 -0.61548000000000003 -0.26179900000000006</pose>
        <geometry>
          <capsule>
            <radius>0.040000000000000001</radius>
            <length>0.27712799999999999</length>
          </capsule>
        </geometry>
        <surface>
          <contact>
            <collide_bitmask>255</collide_bitmask>
          </contact>
          <friction>
            <ode>
              <mu>0.69999999999999996</mu>
            </ode>
          </friction>
        </surface>
      </collision>
      <visual name='visual_left_upper_arm'>
        <pose>0.080000000000000002 0.080000000000000002 -0.080000000000000002 0.78539800000000026 -0.61548000000000003 -0.26179900000000006</pose>
        <geometry>
          <capsule>
            <radius>0.040000000000000001</radius>
            <length>0.27712799999999999</length>
          </capsule>
        </geometry>
        <cast_shadows>true</cast_shadows>
        <laser_retro>0</laser_retro>
        <transparency>0</transparency>
        <visibility_flags>4294967295</visibility_flags>
        <material>
          <ambient>0.800000012 0.600000024 0.400000006 1</ambient>
          <diffuse>0.800000012 0.600000024 0.400000006 1</diffuse>
          <specular>0.5 0.5 0.5 1</specular>
          <emissive>0 0 0 1</emissive>
          <render_order>0</render_order>
          <lighting>true</lighting>
          <double_sided>false</double_sided>
          <shader type='pixel'/>
        </material>
      </visual>
    </link>
    <link name='left_upper_arm_dummy_0'>
      <pose relative_to='left_upper_arm'>0 0 0 0 0 0</pose>
      <inertial>
        <pose>0 0 0 0 0 0</pose>
        <mass>9.9999999999999995e-07</mass>
        <inertia>
          <ixx>3.9999999999999998e-07</ixx>
          <ixy>0</ixy>
          <ixz>0</ixz>
          <iyy>3.9999999999999998e-07</iyy>
          <iyz>0</iyz>
          <izz>3.9999999999999998e-07</izz>
        </inertia>
      </inertial>
      <enable_wind>false</enable_wind>
    </link>
    <link name='left_lower_arm'>
      <pose relative_to='left_upper_arm'>0.17999999999999999 0.17999999999999999 -0.17999999999999999 0 0 0</pose>
      <inertial>
        <pose>0.089999999999999997 -0.089999999999999997 0.089999999999999997 -2.3561899999999998 -0.61548000000000003 1.3089999999999999</pose>
        <mass>0.96145800000000003</mass>
        <inertia>
          <ixx>0.0084016200000000003</ixx>
          <ixy>0</ixy>
          <ixz>0</ixz>
          <iyy>0.0084016200000000003</iyy>
          <iyz>0</iyz>
          <izz>0.00044998800000000002</izz>
        </inertia>
      </inertial>
      <enable_wind>false</enable_wind>
      <collision name='collision_left_lower_arm'>
        <pose>0.089999999999999997 -0.089999999999999997 0.089999999999999997 -2.3561899999999998 -0.61548000000000003 1.3089999999999999</pose>
        <geometry>
          <capsule>
            <radius>0.031</radius>
            <length>0.27712799999999999</length>
          </capsule>
        </geometry>
        <surface>
          <contact>
            <collide_bitmask>255</collide_bitmask>
          </contact>
          <friction>
            <ode>
              <mu>0.69999999999999996</mu>
            </ode>
          </friction>
        </surface>
      </collision>
      <visual name='visual_left_lower_arm'>
        <pose>0.089999999999999997 -0.089999999999999997 0.089999999999999997 -2.3561899999999998 -0.61548000000000003 1.3089999999999999</pose>
        <geometry>
          <capsule>
            <radius>0.031</radius>
            <length>0.27712799999999999</length>
          </capsule>
        </geometry>
        <cast_shadows>true</cast_shadows>
        <laser_retro>0</laser_retro>
        <transparency>0</transparency>
        <visibility_flags>4294967295</visibility_flags>
        <material>
          <ambient>0.800000012 0.600000024 0.400000006 1</ambient>
          <diffuse>0.800000012 0.600000024 0.400000006 1</diffuse>
          <specular>0.5 0.5 0.5 1</specular>
          <emissive>0 0 0 1</emissive>
          <render_order>0</render_order>
          <lighting>true</lighting>
          <double_sided>false</double_sided>
          <shader type='pixel'/>
        </material>
      </visual>
    </link>
    <link name='left_hand'>
      <pose relative_to='left_lower_arm'>0.17999999999999999 -0.17999999999999999 0.17999999999999999 0 0 0</pose>
      <inertial>
        <pose>0 0 0 0.78539800000000026 0.61548000000000003 0.26179900000000006</pose>
        <mass>0.26808300000000002</mass>
        <inertia>
          <ixx>0.00017157300000000001</ixx>
          <ixy>0</ixy>
          <ixz>0</ixz>
          <iyy>0.00017157300000000001</iyy>
          <iyz>0</iyz>
          <izz>0.00017157300000000001</izz>
        </inertia>
      </inertial>
      <enable_wind>false</enable_wind>
      <collision name='collision_left_hand'>
        <pose>0 0 0 0.78539800000000026 0.61548000000000003 0.26179900000000006</pose>
        <geometry>
          <sphere>
            <radius>0.040000000000000001</radius>
          </sphere>
        </geometry>
        <surface>
          <contact>
            <collide_bitmask>255</collide_bitmask>
          </contact>
          <friction>
            <ode>
              <mu>0.69999999999999996</mu>
            </ode>
          </friction>
        </surface>
      </collision>
      <visual name='visual_left_hand'>
        <pose>0 0 0 0.78539800000000026 0.61548000000000003 0.26179900000000006</pose>
        <geometry>
          <sphere>
            <radius>0.040000000000000001</radius>
          </sphere>
        </geometry>
        <cast_shadows>true</cast_shadows>
        <laser_retro>0</laser_retro>
        <transparency>0</transparency>
        <visibility_flags>4294967295</visibility_flags>
        <material>
          <ambient>0.800000012 0.600000024 0.400000006 1</ambient>
          <diffuse>0.800000012 0.600000024 0.400000006 1</diffuse>
          <specular>0.5 0.5 0.5 1</specular>
          <emissive>0 0 0 1</emissive>
          <render_order>0</render_order>
          <lighting>true</lighting>
          <double_sided>false</double_sided>
          <shader type='pixel'/>
        </material>
      </visual>
    </link>
    <joint name='fixed_torso_head_joint' type='fixed'>
      <pose>0 0 0 0 0 0</pose>
      <parent>torso</parent>
      <child>head</child>
    </joint>
    <joint name='joint_abdomen_z' type='revolute'>
      <pose>0 0 0.065000000000000002 0 0 0</pose>
      <parent>torso</parent>
      <child>lower_waist_dummy_0</child>
      <axis>
        <xyz>0 0 1</xyz>
        <limit>
          <lower>-0.78539800000000004</lower>
          <upper>0.78539800000000004</upper>
          <effort>inf</effort>
          <velocity>inf</velocity>
          <stiffness>100000000</stiffness>
          <dissipation>1</dissipation>
        </limit>
        <dynamics>
          <spring_reference>0</spring_reference>
          <spring_stiffness>20</spring_stiffness>
          <damping>5</damping>
          <friction>0</friction>
        </dynamics>
      </axis>
    </joint>
    <joint name='joint_abdomen_y' type='revolute'>
      <pose>0 0 0.065000000000000002 0 0 0</pose>
      <parent>lower_waist_dummy_0</parent>
      <child>lower_waist</child>
      <axis>
        <xyz>0 1 0</xyz>
        <limit>
          <lower>-1.3089999999999999</lower>
          <upper>0.52359900000000004</upper>
          <effort>inf</effort>
          <velocity>inf</velocity>
          <stiffness>100000000</stiffness>
          <dissipation>1</dissipation>
        </limit>
        <dynamics>
          <spring_reference>0</spring_reference>
          <spring_stiffness>10</spring_stiffness>
          <damping>5</damping>
          <friction>0</friction>
        </dynamics>
      </axis>
    </joint>
    <joint name='joint_abdomen_x' type='revolute'>
      <pose>0 0 0.10000000000000001 0 0 0</pose>
      <parent>lower_waist</parent>
      <child>pelvis</child>
      <axis>
        <xyz>1 0 0</xyz>
        <limit>
          <lower>-0.61086499999999999</lower>
          <upper>0.61086499999999999</upper>
          <effort>inf</effort>
          <velocity>inf</velocity>
          <stiffness>100000000</stiffness>
          <dissipation>1</dissipation>
        </limit>
        <dynamics>
          <spring_reference>0</spring_reference>
          <spring_stiffness>10</spring_stiffness>
          <damping>5</damping>
          <friction>0</friction>
        </dynamics>
      </axis>
    </joint>
    <joint name='joint_right_hip_x' type='revolute'>
      <pose>0 0 0 0 0 0</pose>
      <parent>pelvis</parent>
      <child>right_thigh_dummy_0</child>
      <axis>
        <xyz>1 0 0</xyz>
        <limit>
          <lower>-0.436332</lower>
          <upper>0.087266499999999997</upper>
          <effort>inf</effort>
          <velocity>inf</velocity>
          <stiffness>100000000</stiffness>
          <dissipation>1</dissipation>
        </limit>
        <dynamics>
          <spring_reference>0</spring_reference>
          <spring_stiffness>10</spring_stiffness>
          <damping>5</damping>
          <friction>0</friction>
        </dynamics>
      </axis>
    </joint>
    <joint name='joint_right_hip_z' type='revolute'>
      <pose>0 0 0 0 0 0</pose>
      <parent>right_thigh_dummy_0</parent>
      <child>right_thigh_dummy_1</child>
      <axis>
        <xyz>0 0 1</xyz>
        <limit>
          <lower>-1.0471999999999999</lower>
          <upper>0.61086499999999999</upper>
          <effort>inf</effort>
          <velocity>inf</velocity>
          <stiffness>100000000</stiffness>
          <dissipation>1</dissipation>
        </limit>
        <dynamics>
          <spring_reference>0</spring_reference>
          <spring_stiffness>10</spring_stiffness>
          <damping>5</damping>
          <friction>0</friction>
        </dynamics>
      </axis>
    </joint>
    <joint name='joint_right_hip_y' type='revolute'>
      <pose>0 0 0 0 0 0</pose>
      <parent>right_thigh_dummy_1</parent>
      <child>right_thigh</child>
      <axis>
        <xyz>0 1 0</xyz>
        <limit>
          <lower>-1.9198599999999999</lower>
          <upper>0.34906599999999999</upper>
          <effort>inf</effort>
          <velocity>inf</velocity>
          <stiffness>100000000</stiffness>
          <dissipation>1</dissipation>
        </limit>
        <dynamics>
          <spring_reference>0</spring_reference>
          <spring_stiffness>20</spring_stiffness>
          <damping>5</damping>
          <friction>0</friction>
        </dynamics>
      </axis>
    </joint>
    <joint name='joint_right_knee' type='revolute'>
      <pose>0 0 0.02 0 0 0</pose>
      <parent>right_thigh</parent>
      <child>right_shin</child>
      <axis>
        <xyz>0 -1 0</xyz>
        <limit>
          <lower>-2.7925300000000002</lower>
          <upper>0.034906600000000003</upper>
          <effort>inf</effort>
          <velocity>inf</velocity>
          <stiffness>100000000</stiffness>
          <dissipation>1</dissipation>
        </limit>
        <dynamics>
          <spring_reference>0</spring_reference>
          <spring_stiffness>1</spring_stiffness>
          <damping>0.20000000000000001</damping>
          <friction>0</friction>
        </dynamics>
      </axis>
    </joint>
    <joint name='joint_right_ankle_y' type='revolute'>
      <pose>0 0 0.080000000000000002 0 0 0</pose>
      <parent>right_shin</parent>
      <child>right_foot_dummy_0</child>
      <axis>
        <xyz>0 1 0</xyz>
        <limit>
          <lower>-0.87266500000000002</lower>
          <upper>0.87266500000000002</upper>
          <effort>inf</effort>
          <velocity>inf</velocity>
          <stiffness>100000000</stiffness>
          <dissipation>1</dissipation>
        </limit>
        <dynamics>
          <spring_reference>0</spring_reference>
          <spring_stiffness>6</spring_stiffness>
          <damping>0.20000000000000001</damping>
          <friction>0</friction>
        </dynamics>
      </axis>
    </joint>
    <joint name='joint_right_ankle_x' type='revolute'>
      <pose>0 0 0.040000000000000001 0 0 0</pose>
      <parent>right_foot_dummy_0</parent>
      <child>right_foot</child>
      <axis>
        <xyz>0.89442699999999997 0 0.447214</xyz>
        <limit>
          <lower>-0.87266500000000002</lower>
          <upper>0.87266500000000002</upper>
          <effort>inf</effort>
          <velocity>inf</velocity>
          <stiffness>100000000</stiffness>
          <dissipation>1</dissipation>
        </limit>
        <dynamics>
          <spring_reference>0</spring_reference>
          <spring_stiffness>3</spring_stiffness>
          <damping>0.20000000000000001</damping>
          <friction>0</friction>
        </dynamics>
      </axis>
    </joint>
    <joint name='joint_left_hip_x' type='revolute'>
      <pose>0 0 0 0 0 0</pose>
      <parent>pelvis</parent>
      <child>left_thigh_dummy_0</child>
      <axis>
        <xyz>-1 0 0</xyz>
        <limit>
          <lower>-0.436332</lower>
          <upper>0.087266499999999997</upper>
          <effort>inf</effort>
          <velocity>inf</velocity>
          <stiffness>100000000</stiffness>
          <dissipation>1</dissipation>
        </limit>
        <dynamics>
          <spring_reference>0</spring_reference>
          <spring_stiffness>10</spring_stiffness>
          <damping>5</damping>
          <friction>0</friction>
        </dynamics>
      </axis>
    </joint>
    <joint name='joint_left_hip_z' type='revolute'>
      <pose>0 0 0 0 0 0</pose>
      <parent>left_thigh_dummy_0</parent>
      <child>left_thigh_dummy_1</child>
      <axis>
        <xyz>0 0 -1</xyz>
        <limit>
          <lower>-1.0471999999999999</lower>
          <upper>0.61086499999999999</upper>
          <effort>inf</effort>
          <velocity>inf</velocity>
          <stiffness>100000000</stiffness>
          <dissipation>1</dissipation>
        </limit>
        <dynamics>
          <spring_reference>0</spring_reference>
          <spring_stiffness>10</spring_stiffness>
          <damping>5</damping>
          <friction>0</friction>
        </dynamics>
      </axis>
    </joint>
    <joint name='joint_left_hip_y' type='revolute'>
      <pose>0 0 0 0 0 0</pose>
      <parent>left_thigh_dummy_1</parent>
      <child>left_thigh</child>
      <axis>
        <xyz>0 1 0</xyz>
        <limit>
          <lower>-1.9198599999999999</lower>
          <upper>0.34906599999999999</upper>
          <effort>inf</effort>
          <velocity>inf</velocity>
          <stiffness>100000000</stiffness>
          <dissipation>1</dissipation>
        </limit>
        <dynamics>
          <spring_reference>0</spring_reference>
          <spring_stiffness>20</spring_stiffness>
          <damping>5</damping>
          <friction>0</friction>
        </dynamics>
      </axis>
    </joint>
    <joint name='joint_left_knee' type='revolute'>
      <pose>0 0 0.02 0 0 0</pose>
      <parent>left_thigh</parent>
      <child>left_shin</child>
      <axis>
        <xyz>0 -1 0</xyz>
        <limit>
          <lower>-2.7925300000000002</lower>
          <upper>0.034906600000000003</upper>
          <effort>inf</effort>
          <velocity>inf</velocity>
          <stiffness>100000000</stiffness>
          <dissipation>1</dissipation>
        </limit>
        <dynamics>
          <spring_reference>0</spring_reference>
          <spring_stiffness>1</spring_stiffness>
          <damping>0.20000000000000001</damping>
          <friction>0</friction>
        </dynamics>
      </axis>
    </joint>
    <joint name='joint_left_ankle_y' type='revolute'>
      <pose>0 0 0.080000000000000002 0 0 0</pose>
      <parent>left_shin</parent>
      <child>left_foot_dummy_0</child>
      <axis>
        <xyz>0 1 0</xyz>
        <limit>
          <lower>-0.87266500000000002</lower>
          <upper>0.87266500000000002</upper>
          <effort>inf</effort>
          <velocity>inf</velocity>
          <stiffness>100000000</stiffness>
          <dissipation>1</dissipation>
        </limit>
        <dynamics>
          <spring_reference>0</spring_reference>
          <spring_stiffness>6</spring_stiffness>
          <damping>0.20000000000000001</damping>
          <friction>0</friction>
        </dynamics>
      </axis>
    </joint>
    <joint name='joint_left_ankle_x' type='revolute'>
      <pose>0 0 0.040000000000000001 0 0 0</pose>
      <parent>left_foot_dummy_0</parent>
      <child>left_foot</child>
      <axis>
        <xyz>0.89442699999999997 0 0.447214</xyz>
        <limit>
          <lower>-0.87266500000000002</lower>
          <upper>0.87266500000000002</upper>
          <effort>inf</effort>
          <velocity>inf</velocity>
          <stiffness>100000000</stiffness>
          <dissipation>1</dissipation>
        </limit>
        <dynamics>
          <spring_reference>0</spring_reference>
          <spring_stiffness>3</spring_stiffness>
          <damping>0.20000000000000001</damping>
          <friction>0</friction>
        </dynamics>
      </axis>
    </joint>
    <joint name='joint_right_shoulder1' type='revolute'>
      <pose>0 0 0 0 0 0</pose>
      <parent>torso</parent>
      <child>right_upper_arm_dummy_0</child>
      <axis>
        <xyz>0.81649700000000003 0.408248 0.408248</xyz>
        <limit>
          <lower>-1.48353</lower>
          <upper>1.0471999999999999</upper>
          <effort>inf</effort>
          <velocity>inf</velocity>
          <stiffness>100000000</stiffness>
          <dissipation>1</dissipation>
        </limit>
        <dynamics>
          <spring_reference>0</spring_reference>
          <spring_stiffness>1</spring_stiffness>
          <damping>0.20000000000000001</damping>
          <friction>0</friction>
        </dynamics>
      </axis>
    </joint>
    <joint name='joint_right_shoulder2' type='revolute'>
      <pose>0 0 0 0 0 0</pose>
      <parent>right_upper_arm_dummy_0</parent>
      <child>right_upper_arm</child>
      <axis>
        <xyz>0 -0.70710700000000004 0.70710700000000004</xyz>
        <limit>
          <lower>-1.48353</lower>
          <upper>1.0471999999999999</upper>
          <effort>inf</effort>
          <velocity>inf</velocity>
          <stiffness>100000000</stiffness>
          <dissipation>1</dissipation>
        </limit>
        <dynamics>
          <spring_reference>0</spring_reference>
          <spring_stiffness>1</spring_stiffness>
          <damping>0.20000000000000001</damping>
          <friction>0</friction>
        </dynamics>
      </axis>
    </joint>
    <joint name='joint_right_elbow' type='revolute'>
      <pose>0 0 0 0 0 0</pose>
      <parent>right_upper_arm</parent>
      <child>right_lower_arm</child>
      <axis>
        <xyz>0 -0.70710700000000004 0.70710700000000004</xyz>
        <limit>
          <lower>-1.5708</lower>
          <upper>0.87266500000000002</upper>
          <effort>inf</effort>
          <velocity>inf</velocity>
          <stiffness>100000000</stiffness>
          <dissipation>1</dissipation>
        </limit>
        <dynamics>
          <spring_reference>0</spring_reference>
          <spring_stiffness>0</spring_stiffness>
          <damping>0.20000000000000001</damping>
          <friction>0</friction>
        </dynamics>
      </axis>
    </joint>
    <joint name='fixed_right_lower_arm_right_hand_joint' type='fixed'>
      <pose>0 0 0 0 0 0</pose>
      <parent>right_lower_arm</parent>
      <child>right_hand</child>
    </joint>
    <joint name='joint_left_shoulder1' type='revolute'>
      <pose>0 0 0 0 0 0</pose>
      <parent>torso</parent>
      <child>left_upper_arm_dummy_0</child>
      <axis>
        <xyz>0.81649700000000003 -0.408248 0.408248</xyz>
        <limit>
          <lower>-1.0471999999999999</lower>
          <upper>1.48353</upper>
          <effort>inf</effort>
          <velocity>inf</velocity>
          <stiffness>100000000</stiffness>
          <dissipation>1</dissipation>
        </limit>
        <dynamics>
          <spring_reference>0</spring_reference>
          <spring_stiffness>1</spring_stiffness>
          <damping>0.20000000000000001</damping>
          <friction>0</friction>
        </dynamics>
      </axis>
    </joint>
    <joint name='joint_left_shoulder2' type='revolute'>
      <pose>0 0 0 0 0 0</pose>
      <parent>left_upper_arm_dummy_0</parent>
      <child>left_upper_arm</child>
      <axis>
        <xyz>0 0.70710700000000004 0.70710700000000004</xyz>
        <limit>
          <lower>-1.0471999999999999</lower>
          <upper>1.48353</upper>
          <effort>inf</effort>
          <velocity>inf</velocity>
          <stiffness>100000000</stiffness>
          <dissipation>1</dissipation>
        </limit>
        <dynamics>
          <spring_reference>0</spring_reference>
          <spring_stiffness>1</spring_stiffness>
          <damping>0.20000000000000001</damping>
          <friction>0</friction>
        </dynamics>
      </axis>
    </joint>
    <joint name='joint_left_elbow' type='revolute'>
      <pose>0 0 0 0 0 0</pose>
      <parent>left_upper_arm</parent>
      <child>left_lower_arm</child>
      <axis>
        <xyz>0 -0.70710700000000004 -0.70710700000000004</xyz>
        <limit>
          <lower>-1.5708</lower>
          <upper>0.87266500000000002</upper>
          <effort>inf</effort>
          <velocity>inf</velocity>
          <stiffness>100000000</stiffness>
          <dissipation>1</dissipation>
        </limit>
        <dynamics>
          <spring_reference>0</spring_reference>
          <spring_stiffness>0</spring_stiffness>
          <damping>0.20000000000000001</damping>
          <friction>0</friction>
        </dynamics>
      </axis>
    </joint>
    <joint name='fixed_left_lower_arm_left_hand_joint' type='fixed'>
      <pose>0 0 0 0 0 0</pose>
      <parent>left_lower_arm</parent>
      <child>left_hand</child>
    </joint>
  </model>
</sdf>
