<?xml version="1.0"?>
<sdf version="1.9">
  <model name="moon_base_dome">
    <static>true</static>

    <link name="main">
      <collision name="BaseRamp_collision">
        <geometry>
          <mesh>
            <uri>meshes/BaseRamp/BaseRamp.dae</uri>
          </mesh>
        </geometry>
      </collision>
      <visual name="BaseRamp_visual">
        <geometry>
          <mesh>
            <uri>meshes/BaseRamp/BaseRamp.dae</uri>
          </mesh>
        </geometry>
      </visual>

      <collision name="DomeEntryWay_collision">
        <geometry>
          <mesh>
            <uri>meshes/DomeEntryWay/DomeEntryWay.dae</uri>
          </mesh>
        </geometry>
      </collision>
      <visual name="DomeEntryWay_visual">
        <geometry>
          <mesh>
            <uri>meshes/DomeEntryWay/DomeEntryWay.dae</uri>
          </mesh>
        </geometry>
      </visual>

      <collision name="DomeOuter_collision">
        <geometry>
          <mesh>
            <uri>meshes/DomeOuter/DomeOuter.dae</uri>
          </mesh>
        </geometry>
      </collision>
      <visual name="DomeOuter_visual">
        <geometry>
          <mesh>
            <uri>meshes/DomeOuter/DomeOuter.dae</uri>
          </mesh>
        </geometry>
      </visual>

      <collision name="OutsideRamp_collision">
        <geometry>
          <mesh>
            <uri>meshes/OutsideRamp/OutsideRamp.dae</uri>
          </mesh>
        </geometry>
      </collision>
      <visual name="OutsideRamp_visual">
        <geometry>
          <mesh>
            <uri>meshes/OutsideRamp/OutsideRamp.dae</uri>
          </mesh>
        </geometry>
      </visual>

      <collision name="Tube_collision">
        <geometry>
          <mesh>
            <uri>meshes/Tube/Tube.dae</uri>
          </mesh>
        </geometry>
      </collision>
      <visual name="Tube_visual">
        <geometry>
          <mesh>
            <uri>meshes/Tube/Tube.dae</uri>
          </mesh>
        </geometry>
      </visual>

      <collision name="DomePt01_collision">
        <geometry>
          <mesh>
            <uri>meshes/DomePt01/DomePt01.dae</uri>
          </mesh>
        </geometry>
      </collision>
      <visual name="DomePt01_visual">
        <geometry>
          <mesh>
            <uri>meshes/DomePt01/DomePt01.dae</uri>
          </mesh>
        </geometry>
      </visual>

      <collision name="DualFanVent_collision">
        <geometry>
          <mesh>
            <uri>meshes/DualFanVent/DualFanVent.dae</uri>
          </mesh>
        </geometry>
      </collision>
      <visual name="DualFanVent_visual">
        <geometry>
          <mesh>
            <uri>meshes/DualFanVent/DualFanVent.dae</uri>
          </mesh>
        </geometry>
      </visual>

      <collision name="DomePt02_collision">
        <geometry>
          <mesh>
            <uri>meshes/DomePt02/DomePt02.dae</uri>
          </mesh>
        </geometry>
      </collision>
      <visual name="DomePt02_visual">
        <geometry>
          <mesh>
            <uri>meshes/DomePt02/DomePt02.dae</uri>
          </mesh>
        </geometry>
      </visual>

      <collision name="OuterWallGate_collision">
        <geometry>
          <mesh>
            <uri>meshes/OuterWallGate/OuterWallGate.dae</uri>
          </mesh>
        </geometry>
      </collision>
      <visual name="OuterWallGate_visual">
        <geometry>
          <mesh>
            <uri>meshes/OuterWallGate/OuterWallGate.dae</uri>
          </mesh>
        </geometry>
      </visual>

      <collision name="OuterWall_collision">
        <geometry>
          <mesh>
            <uri>meshes/OuterWall/OuterWall.dae</uri>
          </mesh>
        </geometry>
      </collision>
      <visual name="OuterWall_visual">
        <geometry>
          <mesh>
            <uri>meshes/OuterWall/OuterWall.dae</uri>
          </mesh>
        </geometry>
      </visual>

      <collision name="StrutBase_collision">
        <geometry>
          <mesh>
            <uri>meshes/StrutBase/StrutBase.dae</uri>
          </mesh>
        </geometry>
      </collision>
      <visual name="StrutBase_visual">
        <geometry>
          <mesh>
            <uri>meshes/StrutBase/StrutBase.dae</uri>
          </mesh>
        </geometry>
      </visual>
    </link>

    <link name="DoorLeft">
      <pose>1.087 117.589 5.195 0 0 0</pose>
      <collision name="collision">
        <geometry>
          <mesh>
            <uri>meshes/Door/Door.dae</uri>
          </mesh>
        </geometry>
      </collision>
      <visual name="visual">
        <geometry>
          <mesh>
            <uri>meshes/Door/Door.dae</uri>
          </mesh>
        </geometry>
      </visual>
    </link>

    <link name="DoorRight">
      <pose>-1.087 117.589 5.195 0 0 3.14159</pose>
      <collision name="collision">
        <geometry>
          <mesh>
            <uri>meshes/Door/Door.dae</uri>
          </mesh>
        </geometry>
      </collision>
      <visual name="visual">
        <geometry>
          <mesh>
            <uri>meshes/Door/Door.dae</uri>
          </mesh>
        </geometry>
      </visual>
    </link>

    <link name="Fan1">
      <pose>6.0 -85.217 8.88 0 0 0</pose>
      <collision name="collision">
        <geometry>
          <mesh>
            <uri>meshes/Fan/Fan.dae</uri>
          </mesh>
        </geometry>
      </collision>
      <visual name="visual">
        <geometry>
          <mesh>
            <uri>meshes/Fan/Fan.dae</uri>
          </mesh>
        </geometry>
      </visual>
    </link>
    <link name="Fan2">
      <pose>-6 -85.217 8.88 0 0 0</pose>
      <collision name="collision">
        <geometry>
          <mesh>
            <uri>meshes/Fan/Fan.dae</uri>
          </mesh>
        </geometry>
      </collision>
      <visual name="visual">
        <geometry>
          <mesh>
            <uri>meshes/Fan/Fan.dae</uri>
          </mesh>
        </geometry>
      </visual>
    </link>
    <joint name="world_joint" type="fixed">
      <parent>world</parent>
      <child>main</child>
    </joint>
    <joint name="fan1_joint" type="revolute">
      <parent>main</parent>
      <child>Fan1</child>
      <axis>
        <xyz>0 1 0</xyz>
      </axis>
    </joint>
    <joint name="fan2_joint" type="revolute">
      <parent>main</parent>
      <child>Fan2</child>
      <axis>
        <xyz>0 1 0</xyz>
      </axis>
    </joint>
    <plugin filename="gz-sim-joint-controller-system" name="gz::sim::systems::JointController">
      <joint_name>fan1_joint</joint_name>
      <initial_velocity>5.0</initial_velocity>
    </plugin>
    <plugin filename="gz-sim-joint-controller-system" name="gz::sim::systems::JointController">
      <joint_name>fan2_joint</joint_name>
      <initial_velocity>5.0</initial_velocity>
    </plugin>

  </model>
</sdf>
