<?xml version="1.0"?>
<sdf version="1.9">
  <model name="moon_base_fan_blade">
    <static>false</static>
    <link name="Fan">
      <collision name="collision">
        <pose>0 0 0 0 0 0</pose>
        <geometry>
          <mesh>
            <uri>meshes/Fan.dae</uri>
          </mesh>
        </geometry>
      </collision>
      <visual name="visual">
        <geometry>
          <mesh>
            <uri>meshes/Fan.dae</uri>
          </mesh>
        </geometry>
        <material>
          <ambient>0.8 0.8 0.8 1</ambient>
          <diffuse>0.8 0.8 0.8 1</diffuse>
          <specular>0.8 0.8 0.8 1</specular>
            <pbr>
              <metal>
                <albedo_map>materials/textures/Fan_Albedo.jpg</albedo_map>
                <normal_map>materials/textures/Fan_Normal.jpg</normal_map>
                <roughness_map>materials/textures/Fan_Roughness.jpg</roughness_map>
                <metalness_map>materials/textures/Fan_Metalness.jpg</metalness_map>
              </metal>
            </pbr>
        </material>

      </visual>
    </link>
    <joint name="fan_joint" type="revolute">
      <parent>world</parent>
      <child>Fan</child>
      <axis>
        <xyz>0 1 0</xyz>
      </axis>
    </joint>
    <plugin filename="gz-sim-joint-controller-system" name="gz::sim::systems::JointController">
      <joint_name>fan_joint</joint_name>
      <initial_velocity>4.0</initial_velocity>
    </plugin>
  </model>
</sdf>
